<?xml version="1.0" ?>
<!-- Generated using onshape-to-robot -->
<!-- Onshape https://cad.onshape.com/documents/6ea4df2c2feb9d034b7d17e7/w/f7f81d80de76a46836fa4b60/e/3381f4ecc1cbedb8efeb0420 -->
<mujoco model="my-robot">
  <compiler angle="radian" meshdir="assets" autolimits="true"/>
  <default>
    <default class="my-robot">
      <joint frictionloss="0.2" armature="0.005"/>
      <default class="visual">
        <geom type="mesh" contype="0" conaffinity="0" group="2"/>
      </default>
      <default class="collision">
    <geom group="3" contype="0" conaffinity="1"/>
      </default>
    </default>
  </default>
  <worldbody>
    <!-- Link refrence -->
    <body name="refrence" pos="0 0 0" quat="1 0 0 0" childclass="my-robot">
      <freejoint name="refrence_freejoint"/>
      <inertial pos="0 0 0" mass="4.62243156" fullinertia="0.029 0.029 0.043 7.682e-5 2.262e-7 -5.775e-7"/>
      <!-- Part refrence -->
      <geom type="mesh" class="visual" pos="0.0489164 -0.0515 0.0282419" quat="1 0 0 0" mesh="refrence" material="refrence_material"/>
        <geom type="mesh" class="collision" pos="0.0489164 -0.0515 0.0282419" quat="1 0 0 0" mesh="refrence" material="refrence_material"/>
      <!-- Frame imu3 -->
      <site group="3" name="imu3" pos="-0.0025 0 -0.0862338" quat="0.707107 0 0 0.707107"/>
      <!-- Frame imu1 -->
      <site group="3" name="imu1" pos="-0.0734307 4.33681e-19 0.045282" quat="0.353553 0.612372 0.612372 0.353553"/>
      <!-- Frame imu2 -->
      <site group="3" name="imu2" pos="0.0759307 0 0.0409518" quat="0.353553 -0.612372 -0.612372 0.353553"/>
      <!-- Link fake_tread -->
      <body name="fake_tread" pos="-0.00757175 0 0.00437155" quat="0.707107 -0.707107 0 0">
        <!-- Joint from refrence to fake_tread -->
        <joint axis="0 0 1" name="rolly1" type="hinge"/>
        <inertial pos="0 0 0" mass="1e-09" fullinertia="1e-09 1e-09 1e-09 0 0 0"/>
        <!-- Part fake_tread -->
        <geom type="mesh" class="visual" pos="0.0564882 -0.0238704 0.032" quat="0.707107 0.707107 -0 -0" mesh="fake_tread" material="fake_tread_material"/>
        <geom type="mesh" class="collision" pos="0.0564882 -0.0238704 0.032" quat="0.707107 0.707107 -0 -0" mesh="fake_tread" material="fake_tread_material"/>
        <!-- Part fake_tread_2 -->
        <geom type="mesh" class="visual" pos="0.0564882 -0.0238704 -0.078" quat="0.707107 0.707107 -0 -0" mesh="fake_tread" material="fake_tread_material"/>
        <geom type="mesh" class="collision" pos="0.0564882 -0.0238704 -0.078" quat="0.707107 0.707107 -0 -0" mesh="fake_tread" material="fake_tread_material"/>
      </body>
            <!-- Link fake_tread_2 -->
      <body name="fake_tread_2" pos="0.00757175 0 0.00437155" quat="0.707107 -0.707107 0 0">
        <!-- Joint from refrence to fake_tread_2 -->
        <joint axis="0 0 1" name="rolly2" type="hinge"/>
        <inertial pos="0 0 0" mass="1e-09" fullinertia="1e-09 1e-09 1e-09 0 0 0"/>
        <!-- Part fake_tread_3 -->
        <geom type="mesh" class="visual" pos="0.0564882 -0.0238704 -0.078" quat="0.707107 0.707107 -0 -0" mesh="fake_tread" material="fake_tread_material1"/>
        <geom type="mesh" class="collision" pos="0.0564882 -0.0238704 -0.078" quat="0.707107 0.707107 -0 -0" mesh="fake_tread" material="fake_tread_material1"/>
        <!-- Part fake_tread_4 -->
        <geom type="mesh" class="visual" pos="0.0564882 -0.0238704 0.032" quat="0.707107 0.707107 -0 -0" mesh="fake_tread" material="fake_tread_material1"/>
        <geom type="mesh" class="collision" pos="0.0564882 -0.0238704 0.032" quat="0.707107 0.707107 -0 -0" mesh="fake_tread" material="fake_tread_material1"/>
      </body>
      <!-- Link fake_tread_3 -->
      <body name="fake_tread_3" pos="-4.85723e-17 0 -0.0087431" quat="0.707107 0.707107 -0 -0">
        <!-- Joint from refrence to fake_tread_3 -->
        <joint axis="0 0 -1" name="rolly3" type="hinge"/>
        <inertial pos="0 0 0" mass="1e-09" fullinertia="1e-09 1e-09 1e-09 0 0 0"/>
        <!-- Part fake_tread_5 -->
        <geom type="mesh" class="visual" pos="0.0564882 0.0238704 0.078" quat="0.707107 -0.707107 0 0" mesh="fake_tread" material="fake_tread_material2"/>
        <geom type="mesh" class="collision" pos="0.0564882 0.0238704 0.078" quat="0.707107 -0.707107 0 0" mesh="fake_tread" material="fake_tread_material2"/>
        <!-- Part fake_tread_6 -->
        <geom type="mesh" class="visual" pos="0.0564882 0.0238704 -0.032" quat="0.707107 -0.707107 0 0" mesh="fake_tread" material="fake_tread_material2"/>
        <geom type="mesh" class="collision" pos="0.0564882 0.0238704 -0.032" quat="0.707107 -0.707107 0 0" mesh="fake_tread" material="fake_tread_material2"/>
      </body>

    </body>
  </worldbody>
  <asset>
    <mesh file="refrence.stl"/>
    <mesh file="fake_tread.stl"/>
    <material name="refrence_material" rgba="0 0 0 1"/>
    <material name="fake_tread_material" rgba="1 0 0 1"/>
    <material name="fake_tread_material1" rgba="0 1 0 1"/>
    <material name="fake_tread_material2" rgba="0 0 1 1"/>

  </asset>
  <actuator>
    <velocity class="my-robot" name="rolly1" joint="rolly1" kv="1"/>
    <velocity class="my-robot" name="rolly2" joint="rolly2" kv="1"/>
    <velocity class="my-robot" name="rolly3" joint="rolly3" kv="1"/>
  </actuator>

  <sensor>
    <accelerometer name="imu1_accel" site="imu1"/>
    <accelerometer name="imu2_accel" site="imu2"/>
    <accelerometer name="imu3_accel" site="imu3"/>
    <gyro name="imu1_gyro" site="imu1"/>
    <gyro name="imu2_gyro" site="imu2"/>
    <gyro name="imu3_gyro" site="imu3"/>

  </sensor>

  <equality/>
</mujoco>
