<?xml version="1.0" ?>
<!-- Generated using onshape-to-robot -->
<!-- Onshape https://cad.onshape.com/documents/6ea4df2c2feb9d034b7d17e7/w/f7f81d80de76a46836fa4b60/e/3381f4ecc1cbedb8efeb0420 -->
<mujoco model="my-robot">
  <compiler angle="radian" meshdir="assets" autolimits="true"/>
  <default>
    <default class="my-robot">
      <joint frictionloss="0.2" armature="0.005"/>
      <position kp="50" dampratio="1"/>
      <default class="visual">
        <geom type="mesh" contype="0" conaffinity="0" group="2"/>
      </default>
      <default class="collision">
        <geom group="3"/>
      </default>
    </default>
  </default>
  <worldbody>
    <!-- Link refrence -->
    <body name="refrence" pos="0 0 0" quat="1 0 0 0" childclass="my-robot">
      <site group="4" name="center" pos="0 0 0" quat="1 0 0 0"/>

      <freejoint name="refrence_freejoint"/>
      <inertial pos="0 0 0" mass="4.62243156" fullinertia="0.029 0.029 0.043 7.682e-5 2.262e-7 -5.775e-7"/>
      <!-- Part refrence -->
      <geom type="mesh" class="visual" pos="0.0489164 -0.0125 0.0282419" quat="1 0 0 0" mesh="refrence" material="refrence_material"/>
      <geom type="mesh" class="collision" pos="0.0489164 -0.0125 0.0282419" quat="1 0 0 0" mesh="refrence" material="refrence_material"/>
      <!-- Frame rolly3_site -->
      <site group="3" name="rolly3_site" pos="-0.0025 0.0361725 -0.0862338" quat="0.707107 0 0 0.707107"/>
      <!-- Frame rolly1_site -->
      <site group="3" name="rolly1_site" pos="-0.0734307 0.0361725 0.045282" quat="0.353553 0.612372 0.612372 0.353553"/>
      <!-- Frame rolly2_site -->
      <site group="3" name="rolly2_site" pos="0.0759307 0.0361725 0.0409518" quat="0.353553 -0.612372 -0.612372 0.353553"/>
      <!-- Link fake_tread -->
      <body name="fake_tread" pos="-0.0075884 -0.039 0.00438116" quat="0.707107 -0.707107 0 0">
        <!-- Joint from refrence to fake_tread -->
        <joint axis="0 0 1" name="rolly1_L" type="hinge"/>
        <inertial pos="-6.93889e-18 -1.73472e-17 -0.016" mass="0.115553" fullinertia="0.000744985 0.000744985 0.00147025 0 0 0"/>
        <!-- Part fake_tread -->
        <geom type="mesh" class="visual" pos="0.0564882 -0.0238704 0" quat="0.707107 0.707107 -0 -0" mesh="fake_tread" material="fake_tread_material"/>
        <geom type="mesh" class="collision" pos="0.0564882 -0.0238704 0" quat="0.707107 0.707107 -0 -0" mesh="fake_tread" material="fake_tread_material"/>
      </body>
      <!-- Link fake_tread_2 -->
      <body name="fake_tread_2" pos="-0.00757175 0.039 0.00437155" quat="0.5 0.5 -0.5 0.5">
        <!-- Joint from refrence to fake_tread_2 -->
        <joint axis="0 0 1" name="rolly1_R" type="hinge"/>
        <inertial pos="-1.38778e-17 2.08167e-17 -0.016" mass="0.115553" fullinertia="0.000744985 0.000744985 0.00147025 0 0 0"/>
        <!-- Part fake_tread_2 -->
        <geom type="mesh" class="visual" pos="0.0564882 0.0238704 -0.032" quat="0.707107 -0.707107 0 0" mesh="fake_tread" material="fake_tread_material"/>
        <geom type="mesh" class="collision" pos="0.0564882 0.0238704 -0.032" quat="0.707107 -0.707107 0 0" mesh="fake_tread" material="fake_tread_material"/>
      </body>
      <!-- Link fake_tread_3 -->
      <body name="fake_tread_3" pos="0.00757175 -0.039 0.00437155" quat="0.707107 -0.707107 0 0">
        <!-- Joint from refrence to fake_tread_3 -->
        <joint axis="0 0 1" name="rolly2_L" type="hinge"/>
        <inertial pos="-1.38778e-17 2.08167e-17 -0.016" mass="0.115553" fullinertia="0.000744985 0.000744985 0.00147025 0 0 0"/>
        <!-- Part fake_tread_3 -->
        <geom type="mesh" class="visual" pos="0.0564882 0.0238704 -0.032" quat="0.707107 -0.707107 0 0" mesh="fake_tread" material="fake_tread_material1"/>
        <geom type="mesh" class="collision" pos="0.0564882 0.0238704 -0.032" quat="0.707107 -0.707107 0 0" mesh="fake_tread" material="fake_tread_material1"/>
      </body>
      <!-- Link fake_tread_4 -->
      <body name="fake_tread_4" pos="0.00757175 0.039 0.00437155" quat="0.707107 0.707107 -0 -0">
        <!-- Joint from refrence to fake_tread_4 -->
        <joint axis="0 0 1" name="rolly2_R" type="hinge"/>
        <inertial pos="-1.38778e-17 -2.08167e-17 -0.016" mass="0.115553" fullinertia="0.000744985 0.000744985 0.00147025 0 0 0"/>
        <!-- Part fake_tread_4 -->
        <geom type="mesh" class="visual" pos="0.0564882 -0.0238704 0" quat="0.707107 0.707107 -0 -0" mesh="fake_tread" material="fake_tread_material1"/>
        <geom type="mesh" class="collision" pos="0.0564882 -0.0238704 0" quat="0.707107 0.707107 -0 -0" mesh="fake_tread" material="fake_tread_material1"/>
      </body>
      <!-- Link fake_tread_5 -->
      <body name="fake_tread_5" pos="0 -0.039 -0.0087431" quat="0.707107 -0.707107 0 0">
        <!-- Joint from refrence to fake_tread_5 -->
        <joint axis="0 0 1" name="rolly3_L" type="hinge"/>
        <inertial pos="-1.38778e-17 2.42861e-17 -0.016" mass="0.115553" fullinertia="0.000744985 0.000744985 0.00147025 0 0 0"/>
        <!-- Part fake_tread_5 -->
        <geom type="mesh" class="visual" pos="0.0564882 0.0238704 -0.032" quat="0.707107 -0.707107 0 0" mesh="fake_tread" material="fake_tread_material2"/>
        <geom type="mesh" class="collision" pos="0.0564882 0.0238704 -0.032" quat="0.707107 -0.707107 0 0" mesh="fake_tread" material="fake_tread_material2"/>
      </body>
      <!-- Link fake_tread_6 -->
      <body name="fake_tread_6" pos="-6.93889e-18 0.039 -0.0087431" quat="0.707107 0.707107 -1.11022e-16 0">
        <!-- Joint from refrence to fake_tread_6 -->
        <joint axis="0 0 1" name="rolly3_R" type="hinge"/>
        <inertial pos="-6.93889e-18 -2.42861e-17 -0.016" mass="0.115553" fullinertia="0.000744985 0.000744985 0.00147025 0 0 0"/>
        <!-- Part fake_tread_6 -->
        <geom type="mesh" class="visual" pos="0.0564882 -0.0238704 0" quat="0.707107 0.707107 -0 -0" mesh="fake_tread" material="fake_tread_material2"/>
        <geom type="mesh" class="collision" pos="0.0564882 -0.0238704 0" quat="0.707107 0.707107 -0 -0" mesh="fake_tread" material="fake_tread_material2"/>
      </body>
    </body>
  </worldbody>
   <asset>
    <mesh file="refrence.stl"/>
    <mesh file="fake_tread.stl"/>
    <material name="refrence_material" rgba="0 0 0 1"/>
    <material name="fake_tread_material" rgba="1 0 0 1"/>
    <material name="fake_tread_material1" rgba="0 1 0 1"/>
    <material name="fake_tread_material2" rgba="0 0 1 1"/>
  </asset>
  <actuator>
    
    <velocity class="my-robot" name="rolly1_R" joint="rolly1_R" forcerange="-19 19" forcelimited="true" kv="1"/>
    <velocity class="my-robot" name="rolly1_L" joint="rolly1_L" forcerange="-19 19" forcelimited="true" kv="1"/>
    <velocity class="my-robot" name="rolly2_L" joint="rolly2_L" forcerange="-19 19" forcelimited="true" kv="1"/>
    <velocity class="my-robot" name="rolly2_R" joint="rolly2_R" forcerange="-19 19" forcelimited="true" kv="1"/>
    <velocity class="my-robot" name="rolly3_L" joint="rolly3_L" forcerange="-19 19" forcelimited="true" kv="1"/>
    <velocity class="my-robot" name="rolly3_R" joint="rolly3_R" forcerange="-19 19" forcelimited="true" kv="1"/>
  </actuator>


  <sensor>
    <accelerometer name="rolly1_accel" site="rolly1_site"/>
    <accelerometer name="rolly2_accel" site="rolly2_site"/>
    <accelerometer name="rolly3_accel" site="rolly3_site"/>
    <velocimeter name="rolly2_gyro" site="rolly2_site"/>
    <velocimeter name="rolly3_gyro" site="rolly3_site"/>
    <velocimeter name="rolly1_gyro" site="rolly1_site"/>


    <velocimeter name="total_vel" site="center"/>
    <gyro name="total_ang" site="center"/>
    <accelerometer name="total_grav" site="center"/>





  </sensor>

</mujoco>
